{"uuid": "829db935-3834-4c4d-9896-1f732840c04b", "children": ["6f260d3c-747b-48e7-8c2b-b85680ec4d22"], "befores": [{"name": "conn_database", "status": "broken", "statusDetails": {"message": "pymysql.err.OperationalError: (2003, \"Can't connect to MySQL server on 'localhost' ([WinError 10061] 由于目标计算机积极拒绝，无法连接。)\")\n", "trace": "  File \"D:\\python\\Python3.9\\lib\\site-packages\\pluggy\\_callers.py\", line 39, in _multicall\n    res = hook_impl.function(*args)\n  File \"D:\\python\\Python3.9\\lib\\site-packages\\_pytest\\fixtures.py\", line 1128, in pytest_fixture_setup\n    result = call_fixture_func(fixturefunc, request, kwargs)\n  File \"D:\\python\\Python3.9\\lib\\site-packages\\_pytest\\fixtures.py\", line 900, in call_fixture_func\n    fixture_result = next(generator)\n  File \"D:\\pycharm\\py\\request\\conftest.py\", line 9, in conn_database\n    connect = pymysql.connect(host='localhost',\n  File \"D:\\python\\Python3.9\\lib\\site-packages\\pymysql\\connections.py\", line 353, in __init__\n    self.connect()\n  File \"D:\\python\\Python3.9\\lib\\site-packages\\pymysql\\connections.py\", line 664, in connect\n    raise exc\n"}, "start": 1667475921026, "stop": 1667475925134}], "start": 1667475921026, "stop": 1667475925353}